<?xml version="1.0" ?>
<robot xmlns:xacro="http://ros.org/wiki/xacro">
<xacro:macro name="motoman_gp8" params="prefix">
    <xacro:include filename="$(find motoman_resources)/urdf/common_materials.xacro"/>
    <xacro:include filename="$(find motoman_gp8_support)/urdf/gp8_transmission.xacro"/>
    <!-- link list -->
    <link name="${prefix}base_rail">
        <visual>
            <geometry>
                <mesh filename="package://motoman_gp8_support/meshes/visual/slider_barra v1.stl" scale="0.1 0.1 0.1"/>
            </geometry>
            <origin rpy="0 0 0" xyz="0 0 0"/>            
            <xacro:material_yaskawa_silver/>
        </visual>
        <collision>
            <geometry>
                <mesh filename="package://motoman_gp8_support/meshes/collision/slider_barra v1.stl" scale="0.1 0.1 0.1"/>
            </geometry>
            <origin rpy="0 0 0" xyz="0 0 0"/>
        </collision>
        <inertial>
            <mass value="81.012" />
            <inertia ixx="12.087" ixy="0.0" ixz="0.0" iyy="0.11" iyz="0.002" izz="12.125"/>
        </inertial>
    </link>

    <link name="${prefix}base_plate">
        <visual>
            <geometry>
                <mesh filename="package://motoman_gp8_support/meshes/visual/slider_base v1.stl" scale="0.1 0.1 0.1"/>
            </geometry>
            <origin rpy="0 0 0" xyz="0 0 0"/>            
            <xacro:material_yaskawa_silver/>
        </visual>
        <collision>
            <geometry>
                <mesh filename="package://motoman_gp8_support/meshes/collision/slider_base v1.stl" scale="0.1 0.1 0.1"/>
            </geometry>
            <origin rpy="0 0 0" xyz="0 0 0"/>
        </collision>
        <inertial>
            <mass value="4.362" />
            <inertia ixx="0.012" ixy="0.0" ixz="0.0" iyy="0.011" iyz="0.0" izz="0.023" />
        </inertial>
    </link>

    <link name="${prefix}base_link">
        <visual>
            <geometry>
                <mesh filename="package://motoman_gp8_support/meshes/visual/gp8_base_link.stl"/>
            </geometry>
            <xacro:material_red/>
        </visual>
        <collision>
            <geometry>
                <mesh filename="package://motoman_gp8_support/meshes/collision/gp8_base_link.stl"/>
            </geometry>
        </collision>
        <inertial>
            <mass value="10.871" />
            <inertia ixx="0.0587" ixy="0.0" ixz="0.0" iyy="0.0587" iyz="0.0" izz="0.0587" />
        </inertial>
    </link>

    <link name="${prefix}link_1_s">
        <visual>
            <geometry>
                <mesh filename="package://motoman_gp8_support/meshes/visual/gp8_link_1_s.stl"/>
            </geometry>
            <xacro:material_yaskawa_silver/>
        </visual>
        <collision>
            <geometry>
                <mesh filename="package://motoman_gp8_support/meshes/collision/gp8_link_1_s.stl"/>
            </geometry>
        </collision>
        <inertial>
            <mass value="4.594" />
            <inertia ixx="0.016" ixy="0.0" ixz="0.003" iyy="0.02" iyz="0.0" izz="0.02" />
        </inertial>
    </link>

    <link name="${prefix}link_2_l">
        <visual>
            <geometry>
                <mesh filename="package://motoman_gp8_support/meshes/visual/gp8_link_2_l.stl"/>
            </geometry>
            <xacro:material_red/>
        </visual>
        <collision>
            <geometry>
                <mesh filename="package://motoman_gp8_support/meshes/collision/gp8_link_2_l.stl"/>
            </geometry>
        </collision>
        <inertial>
            <mass value="9.979" />
            <inertia ixx="0.168" ixy="0.001" ixz="0.002" iyy="0.117" iyz="0.002" izz="0.117" />
        </inertial>
    </link>

    <link name="${prefix}link_3_u">
        <visual>
            <geometry>
                <mesh filename="package://motoman_gp8_support/meshes/visual/gp8_link_3_u.stl"/>
            </geometry>
            <xacro:material_yaskawa_silver/>
        </visual>
        <collision>
            <geometry>
                <mesh filename="package://motoman_gp8_support/meshes/collision/gp8_link_3_u.stl"/>
            </geometry>
        </collision>
        <inertial>
            <mass value="4.862" />
            <inertia ixx="0.014" ixy="0.0" ixz="0.001" iyy="0.017" iyz="0.0" izz="0.015" />
        </inertial>
    </link>

    <link name="${prefix}link_4_r">
        <visual>
            <geometry>
                <mesh filename="package://motoman_gp8_support/meshes/visual/gp8_link_4_r.stl"/>
            </geometry>
            <xacro:material_red/>
        </visual>
        <collision>
            <geometry>
                <mesh filename="package://motoman_gp8_support/meshes/collision/gp8_link_4_r.stl"/>
            </geometry>
        </collision>
        <inertial>
            <mass value="3.891" />
            <inertia ixx="0.006" ixy="0.0" ixz="0.0" iyy="0.023" iyz="0.0" izz="0.024" />
        </inertial>
    </link>

    <link name="${prefix}link_5_b">
        <visual>
            <geometry>
                <mesh filename="package://motoman_gp8_support/meshes/visual/gp8_link_5_b.stl"/>
            </geometry>
            <xacro:material_yaskawa_silver/>
        </visual>
        <collision>
            <geometry>
                <mesh filename="package://motoman_gp8_support/meshes/collision/gp8_link_5_b.stl"/>
            </geometry>
        </collision>
        <inertial>
            <mass value="0.747" />
            <inertia ixx="0.0000001" ixy="0.0" ixz="0.0" iyy="0.001" iyz="0.0" izz="0.001" />
        </inertial>
    </link>

    <link name="${prefix}link_6_t">
        <visual>
            <geometry>
                <mesh filename="package://motoman_gp8_support/meshes/visual/gp8_link_6_t.stl"/>
            </geometry>
            <xacro:material_red/>
        </visual>
        <collision>
            <geometry>
                <mesh filename="package://motoman_gp8_support/meshes/collision/gp8_link_6_t.stl"/>
            </geometry>
        </collision>
        <inertial>
            <mass value="0.03" />
            <inertia ixx="0.0001" ixy="0.0" ixz="0.0" iyy="0.0000066" iyz="0.0" izz="0.0000065" />
        </inertial>
    </link>

    <!-- Used for fixing robot to Gazebo 'base_rail' -->
    <!-- <link name="world"/> -->
    <link name="world">
        <inertial>
        <mass value="0.0000001"/>
        <origin rpy="0 0 0" xyz="0.0 0.0 0.0"/>
        <inertia ixx="0.0000001" ixy="0.0" ixz="0.0" iyy="0.0000001" iyz="0.0" izz="0.0000001"/>
        </inertial>
    </link>

    <joint name="fixed" type="fixed">
        <parent link="world"/>
        <child link="base_rail"/>
    </joint>

    <!-- end of link list -->


    <!-- joint list -->
    <joint name="${prefix}joint_0_s" type="prismatic">
        <parent link="${prefix}base_rail"/>
        <child link="${prefix}base_plate"/>
        <origin xyz="0 0 ${0.076+0.01}" rpy="0 0 0" />
        <axis xyz="0 1 0" />
        <limit lower="-0.5" upper="0.5" effort="150.92" velocity="0.1"/>
        <dynamics damping="50" friction="1"/>
    </joint>

    <joint name="${prefix}joint_01_s" type="fixed">
        <parent link="${prefix}base_plate"/>
        <child link="${prefix}base_link"/>
        <origin xyz="0 0 0" rpy="0 0 0" />
    </joint>

    <joint name="${prefix}joint_1_s" type="revolute">
        <parent link="${prefix}base_link"/>
        <child link="${prefix}link_1_s"/>
        <origin xyz="0 0 0.330" rpy="0 0 0" />
        <axis xyz="0 0 1" />
        <limit lower="-2.9670" upper="2.9670" effort="150.92" velocity="7.9412"/>
        <dynamics damping="50" friction="1"/>
    </joint>

    <joint name="${prefix}joint_2_l" type="revolute">
        <parent link="${prefix}link_1_s"/>
        <child link="${prefix}link_2_l"/>
        <origin xyz="0.040 0 0" rpy="0 0 0" />
        <axis xyz="0 1 0" />
        <limit lower="-1.1344" upper="2.5307" effort="176.4" velocity="6.7495"/>
        <dynamics damping="50" friction="1"/>
    </joint>

    <joint name="${prefix}joint_3_u" type="revolute">
        <parent link="${prefix}link_2_l"/>
        <child link="${prefix}link_3_u"/>
        <origin xyz="0 0 0.345" rpy="0 0 0" />
        <axis xyz="0 -1 0" />
        <limit lower="-1.2217" upper="3.3161" effort="107.56" velocity="9.0757"/>
        <dynamics damping="50" friction="1"/>
    </joint>

    <joint name="${prefix}joint_4_r" type="revolute">
        <parent link="${prefix}link_3_u"/>
        <child link="${prefix}link_4_r"/>
        <origin xyz="0.340 0 0.040" rpy="0 0 0" />
        <axis xyz="-1 0 0" />
        <limit lower="-3.3161" upper="3.3161" effort="55.86" velocity="9.5993"/>
        <dynamics damping="50" friction="1"/>
    </joint>

    <joint name="${prefix}joint_5_b" type="revolute">
        <parent link="${prefix}link_4_r"/>
        <child link="${prefix}link_5_b"/>
        <origin xyz="0 0 0" rpy="0 0 0" />
        <axis xyz="0 -1 0" />
        <limit lower="-2.3561" upper="2.3561" effort="32.68" velocity="9.5993"/>
        <dynamics damping="50" friction="1"/>
    </joint>

    <joint name="${prefix}joint_6_t" type="revolute">
        <parent link="${prefix}link_5_b"/>
        <child link="${prefix}link_6_t"/>
        <origin xyz="0 0 0" rpy="0 0 0" />
        <axis xyz="-1 0 0" />
        <limit lower="-6.2944" upper="6.2944" effort="22.54" velocity="17.4845"/>
        <dynamics damping="50" friction="1"/>
    </joint>

    <!-- end of joint list -->

    <!-- Transmissions -->
    <xacro:simple_jp_trans_v0 name="transmission_h"
                                joint_name="joint_0_s" actuator_name="motor_h"
                                reduction="100"/>
    <xacro:simple_jp_trans_v0 name="transmission_s"
                                joint_name="joint_1_s" actuator_name="motor_s"
                                reduction="300"/>
    <xacro:simple_jp_trans_v0 name="transmission_l"
                                joint_name="joint_2_l" actuator_name="motor_l"
                                reduction="300"/>
    <xacro:simple_jp_trans_v0 name="transmission_u"
                                joint_name="joint_3_u" actuator_name="motor_u"
                                reduction="50"/>
    <xacro:simple_jp_trans_v0 name="transmission_r"
                                joint_name="joint_4_r" actuator_name="motor_r"
                                reduction="30"/>
    <xacro:simple_jp_trans_v0 name="transmission_b"
                                joint_name="joint_5_b" actuator_name="motor_b"
                                reduction="30"/>
    <xacro:simple_jp_trans_v0 name="transmission_t"
                                joint_name="joint_6_t" actuator_name="motor_t"
                                reduction="10"/>



    <gazebo reference="base_rail">
        <selfCollide>true</selfCollide>
        <material>Gazebo/Grey</material>
    </gazebo>
    <gazebo reference="base_plate">
        <selfCollide>true</selfCollide>
        <material>Gazebo/Grey</material>
    </gazebo>
    <gazebo reference="base_link">
        <selfCollide>true</selfCollide>
        <material>Gazebo/Red</material>
    </gazebo>
    <gazebo reference="link_1_s">
        <selfCollide>true</selfCollide>
        <material>Gazebo/Gray</material>
    </gazebo>
    <gazebo reference="link_2_l">
        <selfCollide>true</selfCollide>
        <material>Gazebo/Red</material>
    </gazebo>
    <gazebo reference="link_3_u">
        <selfCollide>true</selfCollide>
        <material>Gazebo/Gray</material>
    </gazebo>
    <gazebo reference="link_4_r">
        <selfCollide>true</selfCollide>
        <material>Gazebo/Red</material>
    </gazebo>
    <gazebo reference="link_5_b">
        <selfCollide>true</selfCollide>
        <material>Gazebo/Gray</material>
    </gazebo>
    <gazebo reference="link_6_t">
        <selfCollide>true</selfCollide>
        <material>Gazebo/Red</material>
    </gazebo>

   <!-- Plugin: ros_control -->
   <gazebo>
     <plugin name="gazebo_ros_control" filename="libgazebo_ros_control.so">
       <robotNamespace>/robot</robotNamespace>
       <legacyModeNS>true</legacyModeNS>
     </plugin>
   </gazebo>


    </xacro:macro>
</robot>